<?xml version="1.0" encoding="utf-8"?>
<!-- =================================================================================== -->
<!-- |    This document was autogenerated by xacro from cbot.urdf.xacro                | -->
<!-- |    EDITING THIS FILE BY HAND IS NOT RECOMMENDED                                 | -->
<!-- =================================================================================== -->
<robot name="cbot" xmlns:xacro="http://www.ros.org/wiki/xacro">
  <!-- Color -->
  <material name="Black">
    <color rgba="0.0 0.0 0.0 1.0"/>
  </material>
  <material name="Blue">
    <color rgba="0.0 0.0 0.8 1.0"/>
  </material>
  <material name="Green">
    <color rgba="0.0 0.8 0.0 1.0"/>
  </material>
  <material name="Gray">
    <color rgba="0.7 0.7 0.7 1.0"/>
  </material>
  <material name="DarkGray">
    <color rgba="0.3 0.3 0.3 1.0"/>
  </material>
  <material name="Red">
    <color rgba="0.8 0.0 0.0 1.0"/>
  </material>
  <material name="White">
    <color rgba="1.0 1.0 1.0 1.0"/>
  </material>
  <material name="Yellow">
    <color rgba="0.8 0.8 0.0 1.0"/>
  </material>
  <!-- in kg-->
  <!-- in kg-->
  <!-- in kg-->
  <!-- base_footprint Definition -->
  <link name="base_footprint"/>
  <!-- base Definition -->
  <link name="base_link">
    <origin rpy="0 0 0" xyz="0 0 0"/>
    <visual>
      <geometry>
        <box size="0.069 0.138 0.050"/>
      </geometry>
      <material name="White"/>
    </visual>
    <inertial>
      <mass value="0.2"/>
      <origin rpy="0 0 0" xyz="0 0 0"/>
      <inertia ixx="0.000359066666667" ixy="0" ixz="0" iyy="0.000121016666667" iyz="0" izz="0.00039675"/>
    </inertial>
  </link>
  <gazebo reference="base_link">
    <material>Gazebo/White</material>
    <turnGravityOff>false</turnGravityOff>
  </gazebo>
  <joint name="base_joint" type="fixed">
    <origin rpy="0 0 0" xyz="0 0 0.045"/>
    <parent link="base_footprint"/>
    <child link="base_link"/>
  </joint>
  <!-- body Definition -->
  <link name="body_link">
    <origin rpy="0 0 0" xyz="0 0 0"/>
    <visual>
      <geometry>
        <cylinder length="0.122" radius="0.069"/>
      </geometry>
      <material name="White"/>
    </visual>
    <inertial>
      <mass value="0.3"/>
      <origin rpy="0 0 0" xyz="0 0 0"/>
      <inertia ixx="0.000729175" ixy="0" ixz="0" iyy="0.000729175" iyz="0" izz="0.00071415"/>
    </inertial>
  </link>
  <gazebo reference="body_link">
    <material>Gazebo/White</material>
    <turnGravityOff>false</turnGravityOff>
  </gazebo>
  <joint name="body_joint" type="fixed">
    <origin rpy="0 0 0" xyz="-0.036 0 0.081"/>
    <parent link="base_footprint"/>
    <child link="body_link"/>
  </joint>
  <!-- sub: l,r 0,1,2,3 etc -->
  <!-- parent: parent link name -->
  <!-- transX transY transZ: xyz position -->
  <link name="wheel_l">
    <visual>
      <origin rpy="1.57079632679 0 0" xyz="0 0 0"/>
      <geometry>
        <cylinder length="0.018" radius="0.033"/>
      </geometry>
      <material name="Red"/>
    </visual>
    <collision>
      <origin rpy="1.57079632679 0 0" xyz="0 0 0"/>
      <geometry>
        <cylinder length="0.018" radius="0.033"/>
      </geometry>
    </collision>
    <inertial>
      <mass value="0.1"/>
      <origin xyz="0 0 0"/>
      <inertia ixx="2.9925e-05" ixy="0" ixz="0" iyy="2.9925e-05" iyz="0" izz="5.445e-05"/>
    </inertial>
  </link>
  <gazebo reference="wheel_l">
    <material>Gazebo/Red</material>
    <turnGravityOff>false</turnGravityOff>
    <mu1 value="1.0"/>
    <mu2 value="1.0"/>
    <kp value="10000000.0"/>
    <kd value="1.0"/>
    <fdir1 value="1 0 0"/>
  </gazebo>
  <joint name="wheel_l_joint" type="continuous">
    <parent link="base_footprint"/>
    <child link="wheel_l"/>
    <origin rpy="0 0 0" xyz="0 0.08 0.033"/>
    <axis xyz="0 1 0"/>
    <limit effort="100" velocity="100"/>
    <joint_properties damping="0.0" friction="0.0"/>
  </joint>
  <!-- Transmission is important to link the joints and the controller -->
  <transmission name="wheel_l_joint_trans">
    <type>transmission_interface/SimpleTransmission</type>
    <joint name="wheel_l_joint">
      <hardwareInterface>VelocityJointInterface</hardwareInterface>
    </joint>
    <actuator name="wheel_l_motor">
      <hardwareInterface>VelocityJointInterface</hardwareInterface>
      <mechanicalReduction>1</mechanicalReduction>
    </actuator>
  </transmission>
  <!-- sub: l,r 0,1,2,3 etc -->
  <!-- parent: parent link name -->
  <!-- transX transY transZ: xyz position -->
  <link name="wheel_r">
    <visual>
      <origin rpy="1.57079632679 0 0" xyz="0 0 0"/>
      <geometry>
        <cylinder length="0.018" radius="0.033"/>
      </geometry>
      <material name="Red"/>
    </visual>
    <collision>
      <origin rpy="1.57079632679 0 0" xyz="0 0 0"/>
      <geometry>
        <cylinder length="0.018" radius="0.033"/>
      </geometry>
    </collision>
    <inertial>
      <mass value="0.1"/>
      <origin xyz="0 0 0"/>
      <inertia ixx="2.9925e-05" ixy="0" ixz="0" iyy="2.9925e-05" iyz="0" izz="5.445e-05"/>
    </inertial>
  </link>
  <gazebo reference="wheel_r">
    <material>Gazebo/Red</material>
    <turnGravityOff>false</turnGravityOff>
    <mu1 value="1.0"/>
    <mu2 value="1.0"/>
    <kp value="10000000.0"/>
    <kd value="1.0"/>
    <fdir1 value="1 0 0"/>
  </gazebo>
  <joint name="wheel_r_joint" type="continuous">
    <parent link="base_footprint"/>
    <child link="wheel_r"/>
    <origin rpy="0 0 0" xyz="0 -0.08 0.033"/>
    <axis xyz="0 1 0"/>
    <limit effort="100" velocity="100"/>
    <joint_properties damping="0.0" friction="0.0"/>
  </joint>
  <!-- Transmission is important to link the joints and the controller -->
  <transmission name="wheel_r_joint_trans">
    <type>transmission_interface/SimpleTransmission</type>
    <joint name="wheel_r_joint">
      <hardwareInterface>VelocityJointInterface</hardwareInterface>
    </joint>
    <actuator name="wheel_r_motor">
      <hardwareInterface>VelocityJointInterface</hardwareInterface>
      <mechanicalReduction>1</mechanicalReduction>
    </actuator>
  </transmission>
  <!-- sub: l,r 0,1,2,3 etc -->
  <!-- parent: parent link name -->
  <!-- transX transY transZ: xyz position -->
  <link name="caster_0">
    <visual>
      <origin rpy="0 0 0" xyz="0 0 0"/>
      <geometry>
        <sphere radius="0.02"/>
      </geometry>
      <material name="Black"/>
    </visual>
    <collision>
      <origin rpy="0 0 0" xyz="0 0 0"/>
      <geometry>
        <sphere radius="0.02"/>
      </geometry>
    </collision>
    <inertial>
      <mass value="0.1"/>
      <origin xyz="0 0 0"/>
      <inertia ixx="8e-06" ixy="0" ixz="0" iyy="8e-06" iyz="0" izz="8e-06"/>
    </inertial>
  </link>
  <gazebo reference="caster_0">
    <turnGravityOff>false</turnGravityOff>
    <material>Gazebo/Black</material>
    <mu1 value="0.0"/>
    <mu2 value="0.0"/>
  </gazebo>
  <joint name="caster_0_joint" type="fixed">
    <parent link="base_footprint"/>
    <child link="caster_0"/>
    <origin rpy="0 0 0" xyz="-0.08 0 0.02"/>
  </joint>
  <!-- sub: l,r 0,1,2,3 etc -->
  <!-- parent: parent link name -->
  <!-- transX transY transZ: xyz position -->
  <link name="webcam_0">
    <visual>
      <origin rpy="0 0 0" xyz="0 0 0"/>
      <geometry>
        <box size="0.05 0.05 0.05"/>
      </geometry>
      <material name="Green"/>
    </visual>
  </link>
  <joint name="webcam_0_joint" type="fixed">
    <origin rpy="0 0 0" xyz="0 0 0.167"/>
    <parent link="base_footprint"/>
    <child link="webcam_0"/>
  </joint>
  <gazebo reference="webcam_0">
    <material>Gazebo/Green</material>
    <visualize>true</visualize>
    <turnGravityOff>false</turnGravityOff>
    <sensor name="webcam_0_camera" type="camera">
      <update_rate>10.0</update_rate>
      <camera name="webcam_0_camera">
        <pose>0.025 0 0 0 0 0}</pose>
        <horizontal_fov>1.3962634</horizontal_fov>
        <image>
          <width>800</width>
          <height>600</height>
          <format>R8G8B8</format>
        </image>
        <clip>
          <near>0.02</near>
          <far>300</far>
        </clip>
        <noise>
          <type>gaussian</type>
          <mean>0.0</mean>
          <stddev>0.007</stddev>
        </noise>
      </camera>
      <plugin filename="libgazebo_ros_camera.so" name="camera_controller">
        <alwaysOn>true</alwaysOn>
        <updateRate>0.0</updateRate>
        <cameraName>webcam_0_camera</cameraName>
        <imageTopicName>image_raw</imageTopicName>
        <cameraInfoTopicName>camera_info</cameraInfoTopicName>
        <frameName>webcam_0</frameName>
        <hackBaseline>0.0</hackBaseline>
        <distortionK1>0.0</distortionK1>
        <distortionK2>0.0</distortionK2>
        <distortionK3>0.0</distortionK3>
        <distortionT1>0.0</distortionT1>
        <distortionT2>0.0</distortionT2>
      </plugin>
    </sensor>
  </gazebo>
  <!-- Differential drive controller  -->
  <gazebo>
    <plugin filename="libgazebo_ros_diff_drive.so" name="differential_drive_controller">
      <commandTopic>cmd_vel</commandTopic>
      <odometryTopic>odom</odometryTopic>
      <odometryFrame>odom</odometryFrame>
      <odometrySource>world</odometrySource>
      <robotBaseFrame>base_footprint</robotBaseFrame>
      <publishOdomTF>true</publishOdomTF>
      <publishWheelTF>false</publishWheelTF>
      <publishTf>1</publishTf>
      <publishWheelJointState>false</publishWheelJointState>
      <legacyMode>false</legacyMode>
      <updateRate>30</updateRate>
      <leftJoint>wheel_l_joint</leftJoint>
      <rightJoint>wheel_r_joint</rightJoint>
      <wheelSeparation>0.160</wheelSeparation>
      <wheelDiameter>0.066</wheelDiameter>
      <wheelAcceleration>1.8</wheelAcceleration>
      <wheelTorque>10</wheelTorque>
      <rosDebugLevel>Debug</rosDebugLevel>
    </plugin>
  </gazebo>
</robot>

